<!DOCTYPE html>
<html lang="en">
<head>
    <meta charset="UTF-8">
    <meta http-equiv="X-UA-Compatible" content="IE=edge">
    <meta name="viewport" content="width=device-width, initial-scale=1.0">
    <title>Document</title>
</head>
<body>
    <h1>Obsługa błędów</h1>
    <p>
        <b>Jeśli wynik funkcji asynchronicznej (obietnica) <u>nie jest używany</u> w kodzie zewnętrznym</b>, błędy są obsługiwane w ciele funkcji za pomocą konstrukcji <b>try...catch</b>. Wartość parametru error w bloku catch to błąd, który wygeneruje await, jeśli obietnica zostanie odrzucona.
    </p>
    <script>
const fetchUsers = async () => {
  try {
    const response = await fetch("https://jsonplaceholder.typicode.com/users");
    const users = await response.json();
    console.log(users);
  } catch (error) {
    console.log(error.message);
  }
};

fetchUsers();
    </script>

<p>
    <b>Jeśli wynik funkcji asynchronicznej (obietnica) <u>jest używany</u> w kodzie zewnętrznym (globalnym)</b>, to znaczy poza innymi funkcjami asynchronicznymi, błędy są obsługiwane przez metodę wywołania zwrotnego <b>catch()</b>. Wartość parametru error w metodzie catch() jest błędem, który await wygeneruje, jeśli obietnica zostanie odrzucona.
</p>
<script>
const fetchUsers2 = async () => {
  const response = await fetch("https://jsonplaceholder.typicode.com/users");
  const users = await response.json();
  return users;
};

fetchUsers2()
  .then(users => console.log(users))
  .catch(error => console.log(error));
</script>

<p>

<p>
    <b>Jeśli wynik funkcji asynchronicznej jest używany w innej funkcji asynchronicznej</b>, błędy są obsługiwane za pomocą konstrukcji <b>try...catch</b> . Wartość parametru error w bloku catch to błąd, który wygeneruje await, jeśli obietnica zostanie odrzucona.
</p>
<script>
const fetchUsers3 = async () => {
  const response = await fetch("https://jsonplaceholder.typicode.com/users");
  const users = await response.json();
  return users;
};

const doStuff = async () => {
  try {
    const users = await fetchUsers3();
    console.log(users);
  } catch (error) {
    console.log(error.message);
  }
};

doStuff();
</script>
    To poniżej nie zadziała - await może być użyty tylko w ciele funkcji asynchronicznej.
</p>
<script>
const fetchUsers4 = async () => {
  const response = await fetch("https://jsonplaceholder.typicode.com/users");
  const users = await response.json();
  return users;
};

// ❌ SyntaxError: await is only valid in async function
const users = await fetchUsers4();
</script>
</body>
</html>